<?xml version="1.0" encoding="utf-8"?>
<!-- =================================================================================== -->
<!-- |    This document was autogenerated by xacro from planar_gripper.xacro           | -->
<!-- |    EDITING THIS FILE BY HAND IS NOT RECOMMENDED                                 | -->
<!-- =================================================================================== -->
<sdf version="1.6">
  <model name="planar_gripper">
    <link name="finger1_base">
      <visual name="base_visual">
        <pose>0 0 0 0 0 0</pose>
        <geometry>
          <box>
            <size>0.08 0.08 0.008</size>
          </box>
        </geometry>
        <material>
          <diffuse>0.1 0.1 0.1 1</diffuse>
        </material>
      </visual>
    </link>
    <link name="finger1_link1">
      <pose>0 0 0 0 0 0</pose>
      <inertial>
        <pose>0 0 -0.03811 0 0 0</pose>
        <mass>0.449</mass>
        <inertia>
          <!-- This includes the inertia contributed by the motor shaft
                through the gear ratio N, shifted to the COM.
                See planar_gripper.xacro for the calculation. Note that in
                reality this inertia affects Ixx only, but we repeat the
                calculation in Iyy and Izz to satisfy the triangle inequality.
                This is really a hack for this special 2D case. In 3D, we would
                have to model the motor shaft and gear reduction. -->
          <ixx>1.517311719</ixx>
          <iyy>1.517885744</iyy>
          <izz>1.51776429</izz>
          <ixz>2.8883e-05</ixz>
          <ixy>0</ixy>
          <iyz>0</iyz>
        </inertia>
      </inertial>
      <visual name="link1_visual">
        <pose>0 0 -0.0425 0 0 0</pose>
        <geometry>
          <cylinder>
            <length>0.085</length>
            <radius>0.011</radius>
          </cylinder>
        </geometry>
        <material>
          <diffuse>1 0 0 1</diffuse>
        </material>
      </visual>
      <visual name="link1_joint_visual">
        <pose>0 0 -0.085 0 0 0</pose>
        <geometry>
          <sphere>
            <radius>0.0132</radius>
          </sphere>
        </geometry>
        <material>
          <diffuse>.1 .1 .1 1</diffuse>
        </material>
      </visual>
    </link>
    <joint name="finger1_BaseJoint" type="revolute">
      <child>finger1_link1</child>
      <parent>finger1_base</parent>
      <axis>
        <xyz>1 0 0</xyz>
        <limit>
          <!-- Drake parses a zero effort joint as an un-actuated joint. -->
          <effort>75</effort>
          <lower>-1.570796</lower>
          <upper>1.570796</upper>
        </limit>
        <dynamics>
          <damping>0</damping>
        </dynamics>
        <use_parent_model_frame>1</use_parent_model_frame>
      </axis>
    </joint>
    <link name="finger1_link2">
      <!-- The origin of the link2 frame is located at the MidJoint. -->
      <pose>0 0 -0.085 0 0 0</pose>
      <inertial>
        <pose>0 0 -0.02966 0 0 0</pose>
        <mass>0.104</mass>
        <inertia>
          <!-- This includes the inertia contributed by the motor shaft
                through the gear ratio N, shifted to the COM.
                See planar_gripper.xacro for the calculation. Note that in
                reality this inertia affects Ixx only, but we repeat the
                calculation in Iyy and Izz to satisfy the triangle inequality.
                This is really a hack for this special 2D case. In 3D, we would
                have to model the motor shaft and gear reduction. -->
          <ixx>1.503163102</ixx>
          <iyy>1.503167854</iyy>
          <izz>1.503097413</izz>
          <ixz>6.523e-06</ixz>
          <ixy>0</ixy>
          <iyz>0</iyz>
        </inertia>
      </inertial>
      <visual name="link2_visual">
        <pose>0 0 -0.02 0 0 0</pose>
        <geometry>
          <cylinder>
            <length>0.04</length>
            <radius>0.011</radius>
          </cylinder>
        </geometry>
        <material>
          <diffuse>1 0 0 1</diffuse>
        </material>
      </visual>
      <!--The link 2 collision element extends up to (but not including) the
            sphere fingertip-->
      <collision name="link2_collision">
        <pose>0 0 -0.0299 0 0 0</pose>
        <geometry>
          <box>
            <size> 0.022 0.022 0.0598 </size>
          </box>
        </geometry>
        <material>
          <diffuse>1 0 1 1</diffuse>
        </material>
      </collision>
      <visual name="sensor_visual">
        <pose>0 0 -0.0425 0 0 0</pose>
        <geometry>
          <box>
            <size>0.02 0.02 0.005</size>
          </box>
        </geometry>
        <material>
          <diffuse>.8 .8 .8 1</diffuse>
        </material>
      </visual>
    </link>
    <joint name="finger1_MidJoint" type="revolute">
      <parent>finger1_link1</parent>
      <child>finger1_link2</child>
      <!-- Pose X_CJ of the joint frame J in the frame C of the child link -->
      <pose>0 0 0 0 0 0</pose>
      <axis>
        <xyz>1 0 0</xyz>
        <limit>
          <effort>75</effort>
          <lower>-1.570796</lower>
          <upper>1.570796</upper>
        </limit>
        <dynamics>
          <damping>0</damping>
        </dynamics>
        <use_parent_model_frame>1</use_parent_model_frame>
      </axis>
    </joint>
    <!-- The tip link's mass/inertia values are already included in link 2,
           which welds to this link. Hence, the values here are set to be
           (effectively) zero. Note: This fingertip link and its corresponding
           weld joint allows us to sense forces via MBP's reaction forces
           output port. -->
    <link name="finger1_tip_link">
      <pose>0 0 -0.13 0 0 0</pose>
      <inertial>
        <pose>0 0 -0.0074 0 0 0</pose>
        <mass>1e-7</mass>
        <inertia>
          <ixx>1e-7</ixx>
          <iyy>1e-7</iyy>
          <izz>1e-7</izz>
          <ixy>0</ixy>
          <ixz>0</ixz>
          <iyz>0</iyz>
        </inertia>
      </inertial>
      <visual name="tip_adapter_visual">
        <pose>0 0 -0.00565 0 0 0</pose>
        <geometry>
          <cylinder>
            <length>0.0113</length>
            <radius>0.0145</radius>
          </cylinder>
        </geometry>
        <material>
          <diffuse>.3 .3 .3 1</diffuse>
        </material>
      </visual>
      <visual name="tip_cylinder_visual">
        <pose>0 0 -0.01305 0 0 0</pose>
        <geometry>
          <cylinder>
            <length>0.0035</length>
            <radius>0.01</radius>
          </cylinder>
        </geometry>
        <material>
          <diffuse>.3 .3 .3 1</diffuse>
        </material>
      </visual>
      <visual name="tip_sphere_visual">
        <pose>0 0 -0.0263 0 0 0</pose>
        <geometry>
          <sphere>
            <radius>0.015</radius>
          </sphere>
        </geometry>
        <material>
          <diffuse>1 1 1 1</diffuse>
        </material>
      </visual>
      <collision name="tip_sphere_collision">
        <pose>0 0 -0.0263 0 0 0</pose>
        <geometry>
          <sphere>
            <radius>0.015</radius>
          </sphere>
        </geometry>
        <material>
          <diffuse>1 1 1 1</diffuse>
        </material>
      </collision>
    </link>
    <joint name="finger1_sensor_weldjoint" type="fixed">
      <parent>finger1_link2</parent>
      <child>finger1_tip_link</child>
      <pose>0 0 0 0 0 0</pose>
    </joint>
    <link name="finger2_base">
      <visual name="base_visual">
        <pose>0 0 0 0 0 0</pose>
        <geometry>
          <box>
            <size>0.08 0.08 0.008</size>
          </box>
        </geometry>
        <material>
          <diffuse>0.1 0.1 0.1 1</diffuse>
        </material>
      </visual>
    </link>
    <link name="finger2_link1">
      <pose>0 0 0 0 0 0</pose>
      <inertial>
        <pose>0 0 -0.03811 0 0 0</pose>
        <mass>0.449</mass>
        <inertia>
          <!-- This includes the inertia contributed by the motor shaft
                through the gear ratio N, shifted to the COM.
                See planar_gripper.xacro for the calculation. Note that in
                reality this inertia affects Ixx only, but we repeat the
                calculation in Iyy and Izz to satisfy the triangle inequality.
                This is really a hack for this special 2D case. In 3D, we would
                have to model the motor shaft and gear reduction. -->
          <ixx>1.517311719</ixx>
          <iyy>1.517885744</iyy>
          <izz>1.51776429</izz>
          <ixz>2.8883e-05</ixz>
          <ixy>0</ixy>
          <iyz>0</iyz>
        </inertia>
      </inertial>
      <visual name="link1_visual">
        <pose>0 0 -0.0425 0 0 0</pose>
        <geometry>
          <cylinder>
            <length>0.085</length>
            <radius>0.011</radius>
          </cylinder>
        </geometry>
        <material>
          <diffuse>1 0 0 1</diffuse>
        </material>
      </visual>
      <visual name="link1_joint_visual">
        <pose>0 0 -0.085 0 0 0</pose>
        <geometry>
          <sphere>
            <radius>0.0132</radius>
          </sphere>
        </geometry>
        <material>
          <diffuse>.1 .1 .1 1</diffuse>
        </material>
      </visual>
    </link>
    <joint name="finger2_BaseJoint" type="revolute">
      <child>finger2_link1</child>
      <parent>finger2_base</parent>
      <axis>
        <xyz>1 0 0</xyz>
        <limit>
          <!-- Drake parses a zero effort joint as an un-actuated joint. -->
          <effort>75</effort>
          <lower>-1.570796</lower>
          <upper>1.570796</upper>
        </limit>
        <dynamics>
          <damping>0</damping>
        </dynamics>
        <use_parent_model_frame>1</use_parent_model_frame>
      </axis>
    </joint>
    <link name="finger2_link2">
      <!-- The origin of the link2 frame is located at the MidJoint. -->
      <pose>0 0 -0.085 0 0 0</pose>
      <inertial>
        <pose>0 0 -0.02966 0 0 0</pose>
        <mass>0.104</mass>
        <inertia>
          <!-- This includes the inertia contributed by the motor shaft
                through the gear ratio N, shifted to the COM.
                See planar_gripper.xacro for the calculation. Note that in
                reality this inertia affects Ixx only, but we repeat the
                calculation in Iyy and Izz to satisfy the triangle inequality.
                This is really a hack for this special 2D case. In 3D, we would
                have to model the motor shaft and gear reduction. -->
          <ixx>1.503163102</ixx>
          <iyy>1.503167854</iyy>
          <izz>1.503097413</izz>
          <ixz>6.523e-06</ixz>
          <ixy>0</ixy>
          <iyz>0</iyz>
        </inertia>
      </inertial>
      <visual name="link2_visual">
        <pose>0 0 -0.02 0 0 0</pose>
        <geometry>
          <cylinder>
            <length>0.04</length>
            <radius>0.011</radius>
          </cylinder>
        </geometry>
        <material>
          <diffuse>1 0 0 1</diffuse>
        </material>
      </visual>
      <!--The link 2 collision element extends up to (but not including) the
            sphere fingertip-->
      <collision name="link2_collision">
        <pose>0 0 -0.0299 0 0 0</pose>
        <geometry>
          <box>
            <size> 0.022 0.022 0.0598 </size>
          </box>
        </geometry>
        <material>
          <diffuse>1 0 1 1</diffuse>
        </material>
      </collision>
      <visual name="sensor_visual">
        <pose>0 0 -0.0425 0 0 0</pose>
        <geometry>
          <box>
            <size>0.02 0.02 0.005</size>
          </box>
        </geometry>
        <material>
          <diffuse>.8 .8 .8 1</diffuse>
        </material>
      </visual>
    </link>
    <joint name="finger2_MidJoint" type="revolute">
      <parent>finger2_link1</parent>
      <child>finger2_link2</child>
      <!-- Pose X_CJ of the joint frame J in the frame C of the child link -->
      <pose>0 0 0 0 0 0</pose>
      <axis>
        <xyz>1 0 0</xyz>
        <limit>
          <effort>75</effort>
          <lower>-1.570796</lower>
          <upper>1.570796</upper>
        </limit>
        <dynamics>
          <damping>0</damping>
        </dynamics>
        <use_parent_model_frame>1</use_parent_model_frame>
      </axis>
    </joint>
    <!-- The tip link's mass/inertia values are already included in link 2,
           which welds to this link. Hence, the values here are set to be
           (effectively) zero. Note: This fingertip link and its corresponding
           weld joint allows us to sense forces via MBP's reaction forces
           output port. -->
    <link name="finger2_tip_link">
      <pose>0 0 -0.13 0 0 0</pose>
      <inertial>
        <pose>0 0 -0.0074 0 0 0</pose>
        <mass>1e-7</mass>
        <inertia>
          <ixx>1e-7</ixx>
          <iyy>1e-7</iyy>
          <izz>1e-7</izz>
          <ixy>0</ixy>
          <ixz>0</ixz>
          <iyz>0</iyz>
        </inertia>
      </inertial>
      <visual name="tip_adapter_visual">
        <pose>0 0 -0.00565 0 0 0</pose>
        <geometry>
          <cylinder>
            <length>0.0113</length>
            <radius>0.0145</radius>
          </cylinder>
        </geometry>
        <material>
          <diffuse>.3 .3 .3 1</diffuse>
        </material>
      </visual>
      <visual name="tip_cylinder_visual">
        <pose>0 0 -0.01305 0 0 0</pose>
        <geometry>
          <cylinder>
            <length>0.0035</length>
            <radius>0.01</radius>
          </cylinder>
        </geometry>
        <material>
          <diffuse>.3 .3 .3 1</diffuse>
        </material>
      </visual>
      <visual name="tip_sphere_visual">
        <pose>0 0 -0.0263 0 0 0</pose>
        <geometry>
          <sphere>
            <radius>0.015</radius>
          </sphere>
        </geometry>
        <material>
          <diffuse>1 1 1 1</diffuse>
        </material>
      </visual>
      <collision name="tip_sphere_collision">
        <pose>0 0 -0.0263 0 0 0</pose>
        <geometry>
          <sphere>
            <radius>0.015</radius>
          </sphere>
        </geometry>
        <material>
          <diffuse>1 1 1 1</diffuse>
        </material>
      </collision>
    </link>
    <joint name="finger2_sensor_weldjoint" type="fixed">
      <parent>finger2_link2</parent>
      <child>finger2_tip_link</child>
      <pose>0 0 0 0 0 0</pose>
    </joint>
    <link name="finger3_base">
      <visual name="base_visual">
        <pose>0 0 0 0 0 0</pose>
        <geometry>
          <box>
            <size>0.08 0.08 0.008</size>
          </box>
        </geometry>
        <material>
          <diffuse>0.1 0.1 0.1 1</diffuse>
        </material>
      </visual>
    </link>
    <link name="finger3_link1">
      <pose>0 0 0 0 0 0</pose>
      <inertial>
        <pose>0 0 -0.03811 0 0 0</pose>
        <mass>0.449</mass>
        <inertia>
          <!-- This includes the inertia contributed by the motor shaft
                through the gear ratio N, shifted to the COM.
                See planar_gripper.xacro for the calculation. Note that in
                reality this inertia affects Ixx only, but we repeat the
                calculation in Iyy and Izz to satisfy the triangle inequality.
                This is really a hack for this special 2D case. In 3D, we would
                have to model the motor shaft and gear reduction. -->
          <ixx>1.517311719</ixx>
          <iyy>1.517885744</iyy>
          <izz>1.51776429</izz>
          <ixz>2.8883e-05</ixz>
          <ixy>0</ixy>
          <iyz>0</iyz>
        </inertia>
      </inertial>
      <visual name="link1_visual">
        <pose>0 0 -0.0425 0 0 0</pose>
        <geometry>
          <cylinder>
            <length>0.085</length>
            <radius>0.011</radius>
          </cylinder>
        </geometry>
        <material>
          <diffuse>1 0 0 1</diffuse>
        </material>
      </visual>
      <visual name="link1_joint_visual">
        <pose>0 0 -0.085 0 0 0</pose>
        <geometry>
          <sphere>
            <radius>0.0132</radius>
          </sphere>
        </geometry>
        <material>
          <diffuse>.1 .1 .1 1</diffuse>
        </material>
      </visual>
    </link>
    <joint name="finger3_BaseJoint" type="revolute">
      <child>finger3_link1</child>
      <parent>finger3_base</parent>
      <axis>
        <xyz>1 0 0</xyz>
        <limit>
          <!-- Drake parses a zero effort joint as an un-actuated joint. -->
          <effort>75</effort>
          <lower>-1.570796</lower>
          <upper>1.570796</upper>
        </limit>
        <dynamics>
          <damping>0</damping>
        </dynamics>
        <use_parent_model_frame>1</use_parent_model_frame>
      </axis>
    </joint>
    <link name="finger3_link2">
      <!-- The origin of the link2 frame is located at the MidJoint. -->
      <pose>0 0 -0.085 0 0 0</pose>
      <inertial>
        <pose>0 0 -0.02966 0 0 0</pose>
        <mass>0.104</mass>
        <inertia>
          <!-- This includes the inertia contributed by the motor shaft
                through the gear ratio N, shifted to the COM.
                See planar_gripper.xacro for the calculation. Note that in
                reality this inertia affects Ixx only, but we repeat the
                calculation in Iyy and Izz to satisfy the triangle inequality.
                This is really a hack for this special 2D case. In 3D, we would
                have to model the motor shaft and gear reduction. -->
          <ixx>1.503163102</ixx>
          <iyy>1.503167854</iyy>
          <izz>1.503097413</izz>
          <ixz>6.523e-06</ixz>
          <ixy>0</ixy>
          <iyz>0</iyz>
        </inertia>
      </inertial>
      <visual name="link2_visual">
        <pose>0 0 -0.02 0 0 0</pose>
        <geometry>
          <cylinder>
            <length>0.04</length>
            <radius>0.011</radius>
          </cylinder>
        </geometry>
        <material>
          <diffuse>1 0 0 1</diffuse>
        </material>
      </visual>
      <!--The link 2 collision element extends up to (but not including) the
            sphere fingertip-->
      <collision name="link2_collision">
        <pose>0 0 -0.0299 0 0 0</pose>
        <geometry>
          <box>
            <size> 0.022 0.022 0.0598 </size>
          </box>
        </geometry>
        <material>
          <diffuse>1 0 1 1</diffuse>
        </material>
      </collision>
      <visual name="sensor_visual">
        <pose>0 0 -0.0425 0 0 0</pose>
        <geometry>
          <box>
            <size>0.02 0.02 0.005</size>
          </box>
        </geometry>
        <material>
          <diffuse>.8 .8 .8 1</diffuse>
        </material>
      </visual>
    </link>
    <joint name="finger3_MidJoint" type="revolute">
      <parent>finger3_link1</parent>
      <child>finger3_link2</child>
      <!-- Pose X_CJ of the joint frame J in the frame C of the child link -->
      <pose>0 0 0 0 0 0</pose>
      <axis>
        <xyz>1 0 0</xyz>
        <limit>
          <effort>75</effort>
          <lower>-1.570796</lower>
          <upper>1.570796</upper>
        </limit>
        <dynamics>
          <damping>0</damping>
        </dynamics>
        <use_parent_model_frame>1</use_parent_model_frame>
      </axis>
    </joint>
    <!-- The tip link's mass/inertia values are already included in link 2,
           which welds to this link. Hence, the values here are set to be
           (effectively) zero. Note: This fingertip link and its corresponding
           weld joint allows us to sense forces via MBP's reaction forces
           output port. -->
    <link name="finger3_tip_link">
      <pose>0 0 -0.13 0 0 0</pose>
      <inertial>
        <pose>0 0 -0.0074 0 0 0</pose>
        <mass>1e-7</mass>
        <inertia>
          <ixx>1e-7</ixx>
          <iyy>1e-7</iyy>
          <izz>1e-7</izz>
          <ixy>0</ixy>
          <ixz>0</ixz>
          <iyz>0</iyz>
        </inertia>
      </inertial>
      <visual name="tip_adapter_visual">
        <pose>0 0 -0.00565 0 0 0</pose>
        <geometry>
          <cylinder>
            <length>0.0113</length>
            <radius>0.0145</radius>
          </cylinder>
        </geometry>
        <material>
          <diffuse>.3 .3 .3 1</diffuse>
        </material>
      </visual>
      <visual name="tip_cylinder_visual">
        <pose>0 0 -0.01305 0 0 0</pose>
        <geometry>
          <cylinder>
            <length>0.0035</length>
            <radius>0.01</radius>
          </cylinder>
        </geometry>
        <material>
          <diffuse>.3 .3 .3 1</diffuse>
        </material>
      </visual>
      <visual name="tip_sphere_visual">
        <pose>0 0 -0.0263 0 0 0</pose>
        <geometry>
          <sphere>
            <radius>0.015</radius>
          </sphere>
        </geometry>
        <material>
          <diffuse>1 1 1 1</diffuse>
        </material>
      </visual>
      <collision name="tip_sphere_collision">
        <pose>0 0 -0.0263 0 0 0</pose>
        <geometry>
          <sphere>
            <radius>0.015</radius>
          </sphere>
        </geometry>
        <material>
          <diffuse>1 1 1 1</diffuse>
        </material>
      </collision>
    </link>
    <joint name="finger3_sensor_weldjoint" type="fixed">
      <parent>finger3_link2</parent>
      <child>finger3_tip_link</child>
      <pose>0 0 0 0 0 0</pose>
    </joint>
  </model>
</sdf>

