<robot
  name="remy_description">
  <link
    name="base_link">
    <inertial>
      <origin
        xyz="0.000574966688148862 0.0121043151479479 0.14390885732606"
        rpy="0 0 0" />
      <mass
        value="8.46822252536056" />
      <inertia
        ixx="0.269087598168183"
        ixy="0.000174113402562132"
        ixz="0.00219659451629178"
        iyy="0.225923332302707"
        iyz="-0.0210595612806915"
        izz="0.0468171836389949" />
    </inertial>
    <visual>
      <origin
        xyz="0 0 0"
        rpy="0 0 0" />
      <geometry>
        <mesh
          filename="../meshes/base_link.obj" />
      </geometry>
      <material
        name="">
        <color
          rgba="0.898039215686275 0.917647058823529 0.929411764705882 1" />
      </material>
    </visual>
  </link>
  <link
    name="right_wheel">
    <inertial>
      <origin
        xyz="1.06187546273085E-18 2.52135245130945E-06 -0.0015908616235798"
        rpy="0 0 0" />
      <mass
        value="2.11820986694096" />
      <inertia
        ixx="0.01"
        ixy="0.01"
        ixz="0.01"
        iyy="0.01"
        iyz="0.01"
        izz="0.01" />
    </inertial>
    <visual>
      <origin
        xyz="0 0 0"
        rpy="0 0 0" />
      <geometry>
        <mesh
          filename="../meshes/right_wheel.obj" />
      </geometry>
      <material
        name="">
        <color
          rgba="0.792156862745098 0.819607843137255 0.933333333333333 1" />
      </material>
    </visual>
    <collision>
      <origin
        xyz="0 0 0"
        rpy="0 0 0" />
      <geometry>
        <mesh
          filename="../meshes/right_wheel.obj" />
      </geometry>
    </collision>
  </link>
  <joint
    name="right_wheel"
    type="continuous">
    <origin
      xyz="-0.241935 0 0"
      rpy="1.5707963267949 -6.81692115950261E-17 -1.5707963267949" />
    <parent
      link="base_link" />
    <child
      link="right_wheel" />
    <axis
      xyz="0 0 -1" />
  </joint>
  <link
    name="left_wheel">
    <inertial>
      <origin
        xyz="-0.00159086162357977 2.52135245130521E-06 -6.22060369643651E-19"
        rpy="0 0 0" />
      <mass
        value="2.11820986694096" />
      <inertia
        ixx="0.01"
        ixy="0.01"
        ixz="0.01"
        iyy="0.01"
        iyz="0.01"
        izz="0.01" />
    </inertial>
    <visual>
      <origin
        xyz="0 0 0"
        rpy="0 0 0" />
      <geometry>
        <mesh
          filename="../meshes/left_wheel.obj" />
      </geometry>
      <material
        name="">
        <color
          rgba="0.792156862745098 0.819607843137255 0.933333333333333 1" />
      </material>
    </visual>
    <collision>
      <origin
        xyz="0 0 0"
        rpy="0 0 0" />
      <geometry>
        <mesh
          filename="../meshes/left_wheel.obj" />
      </geometry>
    </collision>
  </link>
  <joint
    name="left_wheel"
    type="continuous">
    <origin
      xyz="0.241935 0 0"
      rpy="1.5707963267949 0 0" />
    <parent
      link="base_link" />
    <child
      link="left_wheel" />
    <axis
      xyz="1 0 0" />
  </joint>
  <link
    name="lift">
    <inertial>
      <origin
        xyz="0.00751477217216802 0.250772406984837 0.0753077093150405"
        rpy="0 0 0" />
      <mass
        value="1.10311806702314" />
      <inertia
        ixx="0.0522588985971981"
        ixy="0.00440024139003049"
        ixz="0.00198114192191808"
        iyy="0.0122720602436082"
        iyz="-0.014769042122161"
        izz="0.0421392165136061" />
    </inertial>
    <visual>
      <origin
        xyz="0 0 0"
        rpy="0 0 0" />
      <geometry>
        <mesh
          filename="../meshes/lift.obj" />
      </geometry>
      <material
        name="">
        <color
          rgba="0.792156862745098 0.819607843137255 0.933333333333333 1" />
      </material>
    </visual>
  </link>
  <joint
    name="lift"
    type="prismatic">
    <origin
      xyz="0.017399 -0.040484 0.084147"
      rpy="0.2618 1.0643E-16 -3.1416" />
    <parent
      link="base_link" />
    <child
      link="lift" />
    <axis
      xyz="0 0 1" />
    <limit
      lower="0.1"
      upper="0.6"
      effort="0"
      velocity="0" />
  </joint>
  <link
    name="jaco_mount">
    <inertial>
      <origin
        xyz="3.57081916762845E-05 -3.57111682599554E-05 0.00492411468168719"
        rpy="0 0 0" />
      <mass
        value="0.12648183952591" />
      <inertia
        ixx="0"
        ixy="0"
        ixz="0"
        iyy="0"
        iyz="0"
        izz="0" />
    </inertial>
    <visual>
      <origin
        xyz="0 0 0"
        rpy="0 0 0" />
      <geometry>
        <mesh
          filename="../meshes/jaco_mount.obj" />
      </geometry>
      <material
        name="">
        <color
          rgba="0.792156862745098 0.819607843137255 0.933333333333333 1" />
      </material>
    </visual>
  </link>
  <joint
    name="jaco_mount"
    type="fixed">
    <origin
      xyz="0.0173989999999999 0.159412958043339 0.00572157209564689"
      rpy="0.261799387799146 8.34582944186186E-17 -3.14159265358979" />
    <parent
      link="lift" />
    <child
      link="jaco_mount" />
    <axis
      xyz="0 0 0" />
  </joint>
  <link
    name="front_caster_mount">
    <inertial>
      <origin
        xyz="-5.46655959811071E-05 0.00340956997851766 -0.0168502386603693"
        rpy="0 0 0" />
      <mass
        value="0.107382154839307" />
      <inertia
        ixx="0"
        ixy="0"
        ixz="0"
        iyy="0"
        iyz="0"
        izz="0" />
    </inertial>
    <visual>
      <origin
        xyz="0 0 0"
        rpy="0 0 0" />
      <geometry>
        <mesh
          filename="../meshes/front_caster_mount.obj" />
      </geometry>
      <material
        name="">
        <color
          rgba="0.792156862745098 0.819607843137255 0.933333333333333 1" />
      </material>
    </visual>
  </link>
  <joint
    name="front_caster"
    type="continuous">
    <origin
      xyz="0 -0.2286 -0.0033196"
      rpy="0.05236 -2.0274E-17 -0.33749" />
    <parent
      link="base_link" />
    <child
      link="front_caster_mount" />
    <axis
      xyz="0 0.052336 0.99863" />
  </joint>
  <link
    name="front_caster_wheel">
    <inertial>
      <origin
        xyz="8.21500753117599E-08 4.63518112781003E-15 1.83492130254037E-07"
        rpy="0 0 0" />
      <mass
        value="0.185602296468908" />
      <inertia
        ixx="0.01"
        ixy="0.01"
        ixz="0.01"
        iyy="0.01"
        iyz="0.01"
        izz="0.01" />
    </inertial>
    <visual>
      <origin
        xyz="0 0 0"
        rpy="0 0 0" />
      <geometry>
        <mesh
          filename="../meshes/front_caster_wheel.obj" />
      </geometry>
      <material
        name="">
        <color
          rgba="0.250980392156863 0.250980392156863 0.250980392156863 1" />
      </material>
    </visual>
    <collision>
      <origin
        xyz="0 0 0"
        rpy="0 0 0" />
      <geometry>
        <mesh
          filename="../meshes/front_caster_wheel.obj" />
      </geometry>
    </collision>
  </link>
  <joint
    name="front_caster_wheel"
    type="continuous">
    <origin
      xyz="0 0.0294020016396793 -0.0759667553056439"
      rpy="1.5707963267949 -0.616507014377602 -1.57079632679489" />
    <parent
      link="front_caster_mount" />
    <child
      link="front_caster_wheel" />
    <axis
      xyz="0 0 -1" />
  </joint>
  <link
    name="back_caster_mount">
    <inertial>
      <origin
        xyz="-5.46675230128635E-05 0.00340967822128417 -0.0168501983720861"
        rpy="0 0 0" />
      <mass
        value="0.107381888645876" />
      <inertia
        ixx="0"
        ixy="0"
        ixz="0"
        iyy="0"
        iyz="0"
        izz="0" />
    </inertial>
    <visual>
      <origin
        xyz="0 0 0"
        rpy="0 0 0" />
      <geometry>
        <mesh
          filename="../meshes/back_caster_mount.obj" />
      </geometry>
      <material
        name="">
        <color
          rgba="0.792156862745098 0.819607843137255 0.933333333333333 1" />
      </material>
    </visual>
  </link>
  <joint
    name="back_caster"
    type="continuous">
    <origin
      xyz="0 0.2286 -0.00331958737700475"
      rpy="0.0523598775586215 -5.92206520112322E-17 -1.82771088172709" />
    <parent
      link="base_link" />
    <child
      link="back_caster_mount" />
    <axis
      xyz="0 0.0523359562417371 0.998629534754637" />
  </joint>
  <link
    name="back_caster_wheel">
    <inertial>
      <origin
        xyz="8.21500825490262E-08 0 1.83492141758723E-07"
        rpy="0 0 0" />
      <mass
        value="0.185602296468908" />
      <inertia
        ixx="0.01"
        ixy="0.01"
        ixz="0.01"
        iyy="0.01"
        iyz="0.01"
        izz="0.01" />
    </inertial>
    <visual>
      <origin
        xyz="0 0 0"
        rpy="0 0 0" />
      <geometry>
        <mesh
          filename="../meshes/back_caster_wheel.obj" />
      </geometry>
      <material
        name="">
        <color
          rgba="0.250980392156863 0.250980392156863 0.250980392156863 1" />
      </material>
    </visual>
    <collision>
      <origin
        xyz="0 0 0"
        rpy="0 0 0" />
      <geometry>
        <mesh
          filename="../meshes/back_caster_wheel.obj" />
      </geometry>
    </collision>
  </link>
  <joint
    name="back_caster_wheel"
    type="continuous">
    <origin
      xyz="0 0.0294020016398932 -0.0759667553055578"
      rpy="1.5707963267949 -0.616507014374687 -1.5707963267949" />
    <parent
      link="back_caster_mount" />
    <child
      link="back_caster_wheel" />
    <axis
      xyz="0 0 -1" />
  </joint>

<transmission name="r_wheel_joint">
  <type>transmission_interface/SimpleTransmission</type>
  <joint name="right_wheel">
  </joint>
  <actuator name="r_wheel_joint">
    <mechanicalReduction>1</mechanicalReduction>
  </actuator>
</transmission>
<transmission name="l_wheel_joint">
  <type>transmission_interface/SimpleTransmission</type>
  <joint name="left_wheel">
  </joint>
  <actuator name="l_wheel_joint">
    <mechanicalReduction>1</mechanicalReduction>
  </actuator>
</transmission>
<transmission name="lift_joint">
  <type>transmission_interface/SimpleTransmission</type>
  <joint name="lift">
  </joint>
  <actuator name="lift_joint">
    <mechanicalReduction>1</mechanicalReduction>
  </actuator>
</transmission>

</robot>