<robot
  name="remy_description">
  <link
    name="base_link">
    <inertial>
      <origin
        xyz="0.00087655445154326 0.0133266943334383 0.112028231494976"
        rpy="0 0 0" />
      <mass
        value="3.7861195695851" />
      <inertia
        ixx="0.150559432564579"
        ixy="-0.000110335078785947"
        ixz="0.00175276185527145"
        iyy="0.104289190802925"
        iyz="-0.00679500712897134"
        izz="0.0484042366566965" />
    </inertial>
    <visual>
      <origin
        xyz="0 0 0"
        rpy="0 0 0" />
      <geometry>
        <mesh
          filename="../meshes/base_link.obj" />
      </geometry>
      <material
        name="">
        <color
          rgba="0.792156862745098 0.819607843137255 0.933333333333333 1" />
      </material>
    </visual>
    <collision>
      <origin
        xyz="0 0 0"
        rpy="0 0 0" />
      <geometry>
        <mesh
          filename="../meshes/base_link.obj" />
      </geometry>
    </collision>
  </link>
  <link
    name="right_wheel">
    <inertial>
      <origin
        xyz="1.12828713364064E-18 2.52135245130946E-06 -0.00159086162357974"
        rpy="0 0 0" />
      <mass
        value="2.11820986694096" />
      <inertia
        ixx="2.27083675625833E-05"
        ixy="6.07246295272317E-24"
        ixz="-5.0220569924691E-22"
        iyy="2.27050479385731E-05"
        iyz="2.74540019465214E-07"
        izz="3.31962401012648E-09" />
    </inertial>
    <visual>
      <origin
        xyz="0 0 0"
        rpy="0 0 0" />
      <geometry>
        <mesh
          filename="../meshes/right_wheel.obj" />
      </geometry>
      <material
        name="">
        <color
          rgba="0.792156862745098 0.819607843137255 0.933333333333333 1" />
      </material>
    </visual>
    <collision>
      <origin
        xyz="0 0 0"
        rpy="0 0 0" />
      <geometry>
        <mesh
          filename="../meshes/right_wheel.obj" />
      </geometry>
    </collision>
  </link>
  <joint
    name="right_wheel"
    type="continuous">
    <origin
      xyz="-0.241935 0 0"
      rpy="1.5707963267949 -6.81692115950261E-17 -1.5707963267949" />
    <parent
      link="base_link" />
    <child
      link="right_wheel" />
    <axis
      xyz="0 0 -1" />
  </joint>
  <link
    name="left_wheel">
    <inertial>
      <origin
        xyz="-0.00159086162357977 2.52135245130518E-06 -5.90429117867095E-19"
        rpy="0 0 0" />
      <mass
        value="2.11820986694096" />
      <inertia
        ixx="3.31962401012656E-09"
        ixy="2.74540019465217E-07"
        ixz="6.67663787669261E-22"
        iyy="2.27050479385731E-05"
        iyz="-8.0731135102135E-24"
        izz="2.27083675625832E-05" />
    </inertial>
    <visual>
      <origin
        xyz="0 0 0"
        rpy="0 0 0" />
      <geometry>
        <mesh
          filename="../meshes/left_wheel.obj" />
      </geometry>
      <material
        name="">
        <color
          rgba="0.792156862745098 0.819607843137255 0.933333333333333 1" />
      </material>
    </visual>
    <collision>
      <origin
        xyz="0 0 0"
        rpy="0 0 0" />
      <geometry>
        <mesh
          filename="../meshes/left_wheel.obj" />
      </geometry>
    </collision>
  </link>
  <joint
    name="left_wheel"
    type="continuous">
    <origin
      xyz="0.241935 0 0"
      rpy="1.5707963267949 0 0" />
    <parent
      link="base_link" />
    <child
      link="left_wheel" />
    <axis
      xyz="1 0 0" />
  </joint>
  <link
    name="lift">
    <inertial>
      <origin
        xyz="0.00751477186770951 0.244073400771487 0.050306859069805"
        rpy="0 0 0" />
      <mass
        value="1.10311860062385" />
      <inertia
        ixx="0.0491475524599438"
        ixy="0.00436777029574092"
        ixz="0.00185995768109951"
        iyy="0.0102526980754837"
        iyz="-0.0124608198341577"
        izz="0.0410472324394515" />
    </inertial>
    <visual>
      <origin
        xyz="0 0 0"
        rpy="0 0 0" />
      <geometry>
        <mesh
          filename="../meshes/lift.obj" />
      </geometry>
      <material
        name="">
        <color
          rgba="0.792156862745098 0.819607843137255 0.933333333333333 1" />
      </material>
    </visual>
    <collision>
      <origin
        xyz="0 0 0"
        rpy="0 0 0" />
      <geometry>
        <mesh
          filename="../meshes/lift.obj" />
      </geometry>
    </collision>
  </link>
  <joint
    name="lift"
    type="prismatic">
    <origin
      xyz="0.017399 -0.033223 0.11124"
      rpy="0.2618 1.0643E-16 -3.1416" />
    <parent
      link="base_link" />
    <child
      link="lift" />
    <axis
      xyz="0 0 1" />
    <limit
      lower="0"
      upper="0.6"
      effort="0"
      velocity="0" />
  </joint>

  <transmission name="r_wheel_joint">
    <type>transmission_interface/SimpleTransmission</type>
    <joint name="right_wheel">
    </joint>
    <actuator name="r_wheel_joint">
      <mechanicalReduction>1</mechanicalReduction>
    </actuator>
  </transmission>
  <transmission name="l_wheel_joint">
    <type>transmission_interface/SimpleTransmission</type>
    <joint name="left_wheel">
    </joint>
    <actuator name="l_wheel_joint">
      <mechanicalReduction>1</mechanicalReduction>
    </actuator>
  </transmission>
  <transmission name="lift_joint">
    <type>transmission_interface/SimpleTransmission</type>
    <joint name="lift">
    </joint>
    <actuator name="lift_joint">
      <mechanicalReduction>1</mechanicalReduction>
    </actuator>
  </transmission>

</robot>
