<?xml version="1.0"?>
<sdf version='1.6'>
<model name="brick">
  <link name="brick_base">
    <inertial>
      <pose frame=''>0 0 0 0 0 0 </pose>
      <mass>0.028</mass>
        <inertia>
          <ixx>1.17e-5</ixx>
          <ixy>0</ixy>
          <ixz>0</ixz>
          <iyy>1.9e-5</iyy>
          <iyz>0</iyz>
          <izz>1.9e-5</izz>
        </inertia>
    </inertial>
    <visual name='base_visual_1'>
      <pose frame=''>0 0 0.025 0 0 0</pose>
      <geometry>
        <box>
          <size>0.07 0.1 0.05</size>
        </box>
      </geometry>
      <material>
        <diffuse>0 0.8 0 0.2</diffuse>
      </material>
    </visual>
    <visual name='base_visual_2'>
      <pose frame=''>0 0 -0.025 0 0 0</pose>
      <geometry>
        <box>
          <size>0.07 0.1 0.05</size>
        </box>
      </geometry>
      <material>
        <diffuse>0 0 0.8 0.2</diffuse>
      </material>
    </visual>
    <collision name='box_collision'>
      <pose>0 0 0 0 0 0</pose>
      <geometry>
        <box>
          <size>0.07 0.1 0.1</size>
        </box>
      </geometry>
    </collision>
   </link>
   <joint name="brick_pin_joint" type="revolute">
     <parent>world</parent>
     <child>brick_base</child>
     <axis>
       <xyz> 1 0 0 </xyz>
       <limit>
         <!-- Drake parses a zero effort joint as an un-actuated joint. -->
         <effort> 0 </effort>
       </limit>
       <dynamics>
         <!--        <damping>1e-3</damping>-->
         <damping>0</damping>
       </dynamics>
       <use_parent_model_frame>1</use_parent_model_frame>
     </axis>
   </joint>
</model>
</sdf>
