<?xml version="1.0"?>
<sdf version='1.6'>
<model name="brick">
  <link name="brick_base_link">
  </link>
  <link name="brick_link">
    <inertial>
      <pose frame=''>0 0 0 0 0 0 </pose>
      <mass>1.0</mass>
        <inertia>
          <ixx>1.666667e-3</ixx>
          <ixy>0</ixy>
          <ixz>0</ixz>
          <iyy>1.241667e-3</iyy>
          <iyz>0</iyz>
          <izz>1.241667e-3</izz>
        </inertia>
    </inertial>
    <visual name='brick_visual_1'>
      <pose frame=''>0 0 0.025 0 0 0</pose>
      <geometry>
        <box>
          <size>0.07 0.1 0.05</size>
        </box>
      </geometry>
      <material>
        <diffuse>0 0.8 0 0.2</diffuse>
      </material>
    </visual>
    <visual name='brick_visual_2'>
      <pose frame=''>0 0 -0.025 0 0 0</pose>
      <geometry>
        <box>
          <size>0.07 0.1 0.05</size>
        </box>
      </geometry>
      <material>
        <diffuse>0 0 0.8 0.2</diffuse>
      </material>
    </visual>
    <collision name='box_collision'>
      <pose>0 0 0 0 0 0</pose>
      <geometry>
        <box>
          <size>0.07 0.1 0.1</size>
        </box>
      </geometry>
    </collision>
    <collision name='sphere1_collision'>
      <pose>-0.035 0.05 0.05 0 0 0</pose>
      <geometry>
        <sphere>
<!--          TODO(rcory) I'm sure this affects that master sim too-->
          <radius>.0003</radius>
        </sphere>
      </geometry>
    </collision>
    <collision name='sphere2_collision'>
      <pose>-0.035 -0.05 0.05 0 0 0</pose>
      <geometry>
        <sphere>
          <radius>.0003</radius>
        </sphere>
      </geometry>
    </collision>
    <collision name='sphere3_collision'>
      <pose>-0.035 0.05 -0.05 0 0 0</pose>
      <geometry>
        <sphere>
          <radius>.0003</radius>
        </sphere>
      </geometry>
    </collision>
    <collision name='sphere4_collision'>
      <pose>-0.035 -0.05 -0.05 0 0 0</pose>
      <geometry>
        <sphere>
          <radius>.0003</radius>
        </sphere>
      </geometry>
    </collision>
   </link>
   <joint name="brick_revolute_x_joint" type="revolute">
     <parent>brick_base_link</parent>
     <child>brick_link</child>
     <axis>
       <xyz> 1 0 0 </xyz>
       <limit>
         <!-- Drake parses a zero effort joint as an un-actuated joint. -->
         <effort> 0 </effort>
       </limit>
       <dynamics>
         <damping>.008</damping>
<!--         <damping>.0001</damping>-->
<!--         <damping>.01</damping>-->
       </dynamics>
       <use_parent_model_frame>1</use_parent_model_frame>
     </axis>
   </joint>
</model>
</sdf>
