<?xml version="1.0"?>
<sdf version='1.6'>
<model name="brick">
  <link name="brick_base">
  </link>
  <link name="brick_dummy_link1">
  </link>
  <joint name="brick_translate_y_joint" type="prismatic">
    <child> brick_dummy_link1 </child>
    <parent> brick_base </parent>
    <axis>
      <xyz> 0 1 0 </xyz>
       <!-- Drake parses a zero effort joint as an un-actuated joint. -->
       <effort> 0 </effort>
    </axis>
  </joint>
  <link name="brick_dummy_link2">
  </link>
  <joint name="brick_translate_z_joint" type="prismatic">
    <child> brick_dummy_link2 </child>
    <parent> brick_dummy_link1 </parent>
    <axis>
      <xyz> 0 0 1 </xyz>
       <!-- Drake parses a zero effort joint as an un-actuated joint. -->
       <effort> 0 </effort>
    </axis>
  </joint>
  <link name="brick_link">
    <inertial>
      <pose frame=''>0 0 0 0 0 0 </pose>
      <mass>0.028</mass>
        <inertia>
          <ixx>1.17e-5</ixx>
          <ixy>0</ixy>
          <ixz>0</ixz>
          <iyy>1.9e-5</iyy>
          <iyz>0</iyz>
          <izz>1.9e-5</izz>
        </inertia>
    </inertial>
    <visual name='brick_visual'>
      <pose frame=''>0 0 0 0 0 0</pose>
      <geometry>
        <box>
          <size>0.025 0.092 0.092</size>
        </box>
        <!--<sphere>-->
          <!--<radius>0.1</radius>-->
        <!--</sphere>-->
      </geometry>
      <material>
        <diffuse>0.5 0.5 0.5 1.0</diffuse>
      </material>
    </visual>
    <collision name='box_collision'>
      <pose>0 0 0 0 0 0</pose>
      <geometry>
        <box>
          <size>0.025 0.092 0.092</size>
        </box>
      </geometry>
    </collision>
   </link>
   <joint name="brick_revolute_x_joint" type="revolute">
     <child> brick_link </child>
     <parent> brick_dummy_link2 </parent>
     <axis>
       <xyz> 1 0 0 </xyz>
       <!-- Drake parses a zero effort joint as an un-actuated joint. -->
       <effort> 0 </effort>
     </axis>
   </joint>
</model>
</sdf>
